<?xml version="1.0" ?>


<robot name="m2wr" xmlns:xacro="http://www.ros.org/wiki/xacro">
  <material name="black">
    <color rgba="0.0 0.0 0.0 1.0"/>
  </material>
  <material name="blue">
    <color rgba="0.203125 0.23828125 0.28515625 1.0"/>
  </material>
  <material name="green">
    <color rgba="0.0 0.8 0.0 1.0"/>
  </material>
  <material name="grey">
    <color rgba="0.2 0.2 0.2 1.0"/>
  </material>
  <material name="orange">
    <color rgba="1.0 0.423529411765 0.0392156862745 1.0"/>
  </material>
  <material name="brown">
    <color rgba="0.870588235294 0.811764705882 0.764705882353 1.0"/>
  </material>
  <material name="red">
    <color rgba="0.80078125 0.12890625 0.1328125 1.0"/>
  </material>
  <material name="white">
    <color rgba="1.0 1.0 1.0 1.0"/>
  </material>
  
  <gazebo reference="base_link">
    <material>Gazebo/Orange</material>
  </gazebo>
  <gazebo reference="link_left_wheel">
    <material>Gazebo/Blue</material>
  </gazebo>
  <gazebo reference="link_right_wheel">
    <material>Gazebo/Blue</material>
  </gazebo>
  
 
  
    <link name="base_link">
        <visual>
            <geometry>
                <box size="0.52 0.40 0.05"/>
             </geometry>
             <origin rpy="0 0 0" xyz="0 0 0.3"/>
             <material name ="black"/> 
        </visual>
        <collision name="collision_chassis">
            <geometry>
                <box size="0.52 0.40 0.05"/>
            </geometry>
            <origin rpy="0 0 0" xyz="0 0 0.3"/>
        </collision>
    </link>  

  <link name ="link_back_frame">
    <collision name="collision_back_frame">
        <origin rpy = "0 1.5707 0" xyz="0 0 0"/>
        <material name ="black"/> 
        <geometry>
            <box size="0.46 0.4 0.05"/>
        </geometry>
    </collision>
    <visual name="visual_back_frame">
        <origin rpy = "0 1.5707 0" xyz="0 0 0"/>
        <material name ="black"/> 
        <geometry>
            <box size="0.46 0.4 0.05"/>
        </geometry>
    </visual>
  </link>  

    <joint name="joint_back_frame" type="fixed">
    <origin rpy="0 0 0" xyz="-0.2625 0 0.555"/>
    <child link="link_back_frame"/>
    <parent link="base_link"/>
    <axis rpy="0 0 0" xyz="0 1 0"/>
  </joint>

  <link name="link_right_wheel">
    <collision name="link_right_wheel_collision">
      <origin rpy="0 1.5707 1.5707" xyz="0 0 0"/>
      <geometry>
        <cylinder length="0.04" radius="0.3"/>
      </geometry>
    </collision>
    <visual name="link_right_wheel_visual">
      <origin rpy="0 1.5707 1.5707" xyz="0 0 0"/>
      <geometry>
        <cylinder length="0.04" radius="0.3"/>
      </geometry>
    </visual>
  </link>
  
  <joint name="joint_right_wheel" type="continuous">
    <origin rpy="0 0 0" xyz="-0.26 0.22 0.3"/>
    <child link="link_right_wheel"/>
    <parent link="base_link"/>
    <axis rpy="0 0 0" xyz="0 1 0"/>
    <limit effort="10000" velocity="1000"/>
    <joint_properties damping="1.0" friction="1.0"/>
  </joint>
  
  <link name="link_left_wheel">
    <collision name="link_left_wheel_collision">
      <origin rpy="0 1.5707 1.5707" xyz="0 0 0"/>
      <geometry>
        <cylinder length="0.04" radius="0.3"/>
      </geometry>
    </collision>
    <visual name="link_left_wheel_visual">
      <origin rpy="0 1.5707 1.5707" xyz="0 0 0"/>
      <geometry>
        <cylinder length="0.04" radius="0.3"/>
      </geometry>
    </visual>
  </link>
  
  <joint name="joint_left_wheel" type="continuous">
    <origin rpy="0 0 0" xyz="-0.26 -0.22 0.3"/>
    <child link="link_left_wheel"/>
    <parent link="base_link"/>
    <axis rpy="0 0 0" xyz="0 1 0"/>
    <limit effort="10000" velocity="1000"/>
    <joint_properties damping="1.0" friction="1.0"/>
  </joint>

  <link name="link_support_right_bar">
   <collision name="collision_support_right_bar">
        <origin rpy="0 -1.5707 0" xyz="0 0 0"/>
        <material name ="green"/> 
        <geometry>
            <box size="0.16 0.04 0.04"/>
        </geometry>
   </collision>
   <visual name="visual_support_right_bar">
        <origin rpy = "0 -1.5707 0" xyz="0 0 0"/>
        <material name ="green"/> 
        <geometry>
            <box size="0.16 0.04 0.04"/>
        </geometry>
    </visual>
  </link>

    <joint name="joint_support_right_bar" type="fixed">
    <origin rpy="0 0 0" xyz="0.2420 0.18  0.195"/>
    <child link="link_support_right_bar"/>
    <parent link="base_link"/>
    <axis rpy="0 0 0" xyz="0 1 0"/>
  </joint>

<link name="link_support_left_bar">
   <collision name="collision_support_left_bar">
        <origin rpy="0 -1.5707 0" xyz="0 0 0"/>
        <material name ="green"/> 
        <geometry>
            <box size="0.16 0.04 0.04"/>
        </geometry>
   </collision>
   <visual name="visual_support_left_bar">
        <origin rpy = "0 -1.5707 0" xyz="0 0 0"/>
        <material name ="green"/> 
        <geometry>
            <box size="0.16 0.04 0.04"/>
        </geometry>
    </visual>
  </link>

    <joint name="joint_support_left_bar" type="fixed">
    <origin rpy="0 0 0" xyz="0.2420 -0.18  0.195"/>
    <child link="link_support_left_bar"/>
    <parent link="base_link"/>
    <axis rpy="0 0 0" xyz="0 1 0"/>
  </joint>


  
  <link name="link_support_right_wheel">
    <collision name="link_support_right_left_wheel_collision">
      <origin rpy="0 1.5707 1.5707" xyz="0 0 0"/>
      <geometry>
        <cylinder length="0.04" radius="0.07"/>
      </geometry>
    </collision>
    <visual name="link_support_right_wheel_visual">
      <origin rpy="0 1.5707 1.5707" xyz="0 0 0"/>
      <geometry>
        <cylinder length="0.04" radius="0.07"/>
      </geometry>
    </visual>
  </link>

  <joint name="joint_support_right_wheel" type="continuous">
    <origin rpy="0 0 0" xyz="0.2420 0.22 0.07"/>
    <child link="link_support_right_wheel"/>
    <parent link="base_link"/>
    <axis rpy="0 0 0" xyz="0 1 0"/>
    <limit effort="10000" velocity="1000"/>
    <joint_properties damping="1.0" friction="1.0"/>
  </joint>


  <link name="link_support_left_wheel">
    <collision name="link_support_left_wheel_collision">
      <origin rpy="0 1.5707 1.5707" xyz="0 0 0"/>
      <geometry>
        <cylinder length="0.04" radius="0.07"/>
      </geometry>
    </collision>
    <visual name="link_support_left_wheel_visual">
      <origin rpy="0 1.5707 1.5707" xyz="0 0 0"/>
      <geometry>
        <cylinder length="0.04" radius="0.07"/>
      </geometry>
    </visual>
  </link>

  <joint name="joint_support_left_wheel" type="continuous">
    <origin rpy="0 0 0" xyz="0.2420 -0.22 0.07"/>
    <child link="link_support_left_wheel"/>
    <parent link="base_link"/>
    <axis rpy="0 0 0" xyz="0 1 0"/>
    <limit effort="10000" velocity="1000"/>
    <joint_properties damping="1.0" friction="1.0"/>
  </joint>

</robot>